Traceback (most recent call last):
  File "/Users/nataliesheiko/anaconda3/lib/python3.11/site-packages/jupyter_cache/executors/utils.py", line 58, in single_nb_execution
    executenb(
  File "/Users/nataliesheiko/anaconda3/lib/python3.11/site-packages/nbclient/client.py", line 1204, in execute
    return NotebookClient(nb=nb, resources=resources, km=km, **kwargs).execute()
           ^^^^^^^^^^^^^^^^^^^^^^^^^^^^^^^^^^^^^^^^^^^^^^^^^^^^^^^^^^^^^^^^^^^^^
  File "/Users/nataliesheiko/anaconda3/lib/python3.11/site-packages/nbclient/util.py", line 84, in wrapped
    return just_run(coro(*args, **kwargs))
           ^^^^^^^^^^^^^^^^^^^^^^^^^^^^^^^
  File "/Users/nataliesheiko/anaconda3/lib/python3.11/site-packages/nbclient/util.py", line 62, in just_run
    return loop.run_until_complete(coro)
           ^^^^^^^^^^^^^^^^^^^^^^^^^^^^^
  File "/Users/nataliesheiko/anaconda3/lib/python3.11/asyncio/base_events.py", line 653, in run_until_complete
    return future.result()
           ^^^^^^^^^^^^^^^
  File "/Users/nataliesheiko/anaconda3/lib/python3.11/site-packages/nbclient/client.py", line 663, in async_execute
    await self.async_execute_cell(
  File "/Users/nataliesheiko/anaconda3/lib/python3.11/site-packages/nbclient/client.py", line 965, in async_execute_cell
    await self._check_raise_for_error(cell, cell_index, exec_reply)
  File "/Users/nataliesheiko/anaconda3/lib/python3.11/site-packages/nbclient/client.py", line 862, in _check_raise_for_error
    raise CellExecutionError.from_cell_and_msg(cell, exec_reply_content)
nbclient.exceptions.CellExecutionError: An error occurred while executing the following cell:
------------------
df = pd.read_csv('./dataset/train.csv')
df['Sex']=df['Sex'].apply(lambda x: 1 if x=='male' else 0)
df.loc[df['Age'].isna(),'Age']=-1
X = df[['Sex','Pclass','Age', 'SibSp','Parch','Fare']]
y = df["Survived"]
X_train,X_test, y_train, y_test=train_test_split(X, y, test_size=0.2, random_state=51)
print(X_train.shape)
print(X_test.shape)

------------------

[0;31m---------------------------------------------------------------------------[0m
[0;31mNameError[0m                                 Traceback (most recent call last)
Cell [0;32mIn[5], line 1[0m
[0;32m----> 1[0m df [38;5;241m=[39m pd[38;5;241m.[39mread_csv([38;5;124m'[39m[38;5;124m./dataset/train.csv[39m[38;5;124m'[39m)
[1;32m      2[0m df[[38;5;124m'[39m[38;5;124mSex[39m[38;5;124m'[39m][38;5;241m=[39mdf[[38;5;124m'[39m[38;5;124mSex[39m[38;5;124m'[39m][38;5;241m.[39mapply([38;5;28;01mlambda[39;00m x: [38;5;241m1[39m [38;5;28;01mif[39;00m x[38;5;241m==[39m[38;5;124m'[39m[38;5;124mmale[39m[38;5;124m'[39m [38;5;28;01melse[39;00m [38;5;241m0[39m)
[1;32m      3[0m df[38;5;241m.[39mloc[df[[38;5;124m'[39m[38;5;124mAge[39m[38;5;124m'[39m][38;5;241m.[39misna(),[38;5;124m'[39m[38;5;124mAge[39m[38;5;124m'[39m][38;5;241m=[39m[38;5;241m-[39m[38;5;241m1[39m

[0;31mNameError[0m: name 'pd' is not defined
NameError: name 'pd' is not defined

